Workbook
Name 宕渣: [1]材料单价!$D$18
Name 吊机50: #REF!
Name 风化碎石: #REF!
Name 钢板: #REF!
Name 钢管: #REF!
Name 钢管桩: [1]材料单价!$D$19
Name 钢护筒: #REF!
Name 钢绞线: #REF!
Name 钢筋1: #REF!
Name 钢筋2: #REF!
Name 钢筋涵1: #REF!
Name 钢筋涵1.25: #REF!
Name 结构碎石: #REF!
Name 片石: #REF!
Name 砂: #REF!
Name 砂砾: #REF!
Name 生石灰: #REF!
Name 水泥1: #REF!
Name 水泥2: #REF!
Name 碎石: #REF!
Name 砼拌运: [1]砼拌合站建设!$C$31
Name 土: #REF!
Name 型钢: #REF!
Name 中粗砂: #REF!
Name 八号: EVALUATE(#REF!)
Name 大龙: EVALUATE(#REF!)
Name 二号: EVALUATE(#REF!)
Name 六号: EVALUATE(#REF!)
Name 七号: EVALUATE(#REF!)
Name 三号: EVALUATE(#REF!)
Name 石柱: EVALUATE(#REF!)
Name 四号: EVALUATE(#REF!)
Name 五号: EVALUATE(#REF!)
Name 一号: EVALUATE(#REF!)

Sheet 300章
A1: 清单 第 300 章 路面工程
A2: 子目号 | B2: 子目名称 | C2: 单位 | D2: 数量 | E2: 单价 | F2: 合价
A3: 302 | B3: 垫层
A4: 302-1 | B4: 碎石垫层
A5: 302-1-3 | B5: 厚150mm | C5: m2 | D5: ='302-1-3厚150mm 级配碎石垫层'!E21 -> 9254
A6: 302-8 | B6: 素混凝土垫层
A7: 302-8-7 | B7: 厚400mm | C7: m2 | D7: ='302-8-7厚400mm素混凝土垫层'!D21 -> 1583.5
A8: 303 | B8: 底基层
A9: 303-1 | B9: 水泥稳定碎石底基层
A10: 303-1-5 | B10: 厚200mm | C10: m2 | D10: ='303-1-5 厚200mm水泥稳定碎石底基层'!F21 -> 381.4
A11: 303-1-8 | B11: 厚340mm | C11: m2 | D11: ='303-1-8 厚340mm水泥稳定碎石底基层'!E28 -> 66702
A12: 304-1 | B12: 水泥稳定碎石基层
A13: 304-1-5 | B13: 厚200mm | C13: m2 | D13: ='304-1-5 厚200mm 水泥稳定碎石基层 '!E35 -> 76243.378
A14: 305 | B14: 透层、封层、黏层
A15: 305-2 | B15: 黏层 | C15: m2 | D15: ='305-2 黏层'!E57 -> 183716.54
A16: 305-3-2 | B16: 乳化沥青封层
A17: 305-3-6 | B17: 下封层 | C17: m2 | D17: ='305-3-6 下封层'!E34 -> 70396.378
A18: 305-5-5 | B18: 防水黏结层 | C18: m2 | D18: ='305-5-5 防水黏结层 '!E28 -> 56929.42
A19: 305-6 | B19: 混凝土表面处理
A20: 305-6-2 | B20: 抛丸 | C20: m2 | D20: ='305-6-2 抛丸 '!E15 -> 55449.78
A21: 306 | B21: 沥青混凝土面层
A22: 306-1 | B22: 普通沥青混凝土面层
A23: 306-1-2 | B23: 中粒式沥青混凝土
A24: 306-1-2-3 | B24: 厚60mm | C24: m2
A25: 306-1-3 | B25: 粗粒式沥青混凝土
A26: 306-1-3-4 | B26: 厚80mm | C26: m2 | D26: ='306-1-3-4 厚80mm粗粒式沥青混凝土 '!E28 -> 58489.94
A27: 306-2 | B27: 改性沥青混凝土面层
A28: 306-2-2 | B28: 中粒式改性沥青混凝土
A29: 306-2-2-3 | B29: 厚60mm | C29: m2 | D29: ='306-2-2-3 厚60mm中粒式沥青混凝土'!E55 -> 120392.24
A30: 306-2-2-5 | B30: 厚140mm | C30: m2 | D30: ='306-2-2-5 厚140mm中粒式沥青混凝土 '!E21 -> 5048
A31: 306-3 | B31: 沥青玛蹄脂碎石混合料面层（SMA）
A32: 306-3-1 | B32: 细粒式沥青玛蹄脂碎石混合料面层（SMA）
A33: 306-3-1-2 | B33: 厚40mm | C33: m2 | D33: ='306-3-1-2 厚40mm细粒式沥青玛蹄脂碎石混合料面层'!E57 -> 125033.83
A34: 307 | B34: 水泥混凝土面板
A35: 307-1 | B35: 水泥混凝土面层
A36: 307-1-1 | B36: C30混凝土 | C36: m3 | D36: ='307-1-1 C30混凝土水泥混凝土面层'!F21 -> 649.08
A37: 307-1-2 | B37: C35混凝土 | C37: m3 | D37: ='307-1-2 C35混凝土水泥混凝土面层 '!D21 -> 255
A38: 307-1-4 | B38: C25混凝土 | C38: m3 | D38: ='307-1-3 C25混凝土水泥混凝土面层'!F21 -> 4800
A39: 307-2 | B39: 钢筋
A40: 307-2-2 | B40: 带肋钢筋 | C40: kg | D40: ='307-2-2 带肋钢筋 '!D21 -> 1627.1
...

Sheet 302-1-3厚150mm 级配碎石垫层
A1: 302-1-3厚150mm 级配碎石垫层数量计算表
A2: 序号 | B2: 段落 | C2: 长度（m） | D2: 宽度（m） | E2: 核算数量（m2） | F2: 图纸数量（m2) | G2: 备注
A3: 1 | B3: K7+245-K7+416 | C3: 170.6 | D3: 33 | E3: 5438 | F3: 5438 | G3: 第五册第一分册S6-3-12
A4: 2 | B4: AK0+195-AK0+231 | C4: 36.1 | D4: 渐变段 | E4: 355 | F4: 355 | G4: 第五册第一分册S6-3-12
A5: 3 | B5: AK0+231-AK0+357 | C5: 125.9 | D5: 10.5 | E5: 1304 | F5: 1304 | G5: 第五册第一分册S6-3-12
A6: 4 | B6: BK0+106-BK0+315 | C6: 208.4 | D6: 10.5 | E6: 2157 | F6: 2157 | G6: 第五册第一分册S6-3-12
A21: 合计： | E21: =SUM(E3:E6) -> 9254 | F21: =SUM(F3:F6) -> 9254
A22: 计算： 复核： 监理: 日期:

Sheet 302-8-7厚400mm素混凝土垫层
A1: 302-8-7厚400mm素混凝土垫层 数量计算表
A2: 序号 | B2: 段落 | C2: 位置 | D2: 核算数量（m2） | E2: 图纸数量（m2) | F2: 备注
A3: 1 | B3: K4+456 | C3: 七秩塘桥右幅磐安方向 | D3: =39.6/0.4 -> 99 | E3: =39.6/0.4 -> 99 | F3: 第二册S3-17
A4: 2 | B4: K4+456 | C4: 七秩塘桥右幅东阳方向 | D4: =52.8/0.4 -> 132 | E4: =52.8/0.4 -> 132 | F4: 第二册S3-17
A5: 3 | B5: ZK4+460.5 | C5: 七秩塘桥左幅磐安方向 | D5: =52.8/0.4 -> 132 | E5: =52.8/0.4 -> 132 | F5: 第二册S3-17
A6: 4 | B6: ZK4+460.5 | C6: 七秩塘桥左幅东阳方向 | D6: =39.6/0.4 -> 99 | E6: =39.6/0.4 -> 99 | F6: 第二册S3-17
A7: 5 | B7: K6+960 | C7: 横路店大桥磐安方向 | D7: =105.6/0.4 -> 264 | E7: =105.6/0.4 -> 264 | F7: 第五册第一分册S6-3-4
A8: 6 | B8: K6+960 | C8: 横路店大桥东阳方向 | D8: =136.6/0.4 -> 341.5 | E8: =136.6/0.4 -> 341.5 | F8: 第五册第一分册S6-3-4
A9: 7 | B9: K7+711.6 | C9: 马宅大桥磐安方向 | D9: =105.6/0.4 -> 264 | E9: =105.6/0.4 -> 264 | F9: 第五册第一分册S6-3-4
A10: 8 | B10: AK0+376 | C10: 马宅互通A辅道桥磐安方向 | D10: =25.2/0.4 -> 63 | E10: =25.2/0.4 -> 63 | F10: 第五册第一分册S6-3-4
A11: 9 | B11: AK0+376 | C11: 马宅互通A辅道桥东阳方向 | D11: =25.2/0.4 -> 63 | E11: =25.2/0.4 -> 63 | F11: 第五册第一分册S6-3-4
A12: 10 | B12: BK0+087.6 | C12: 马宅互通B辅道桥磐安方向 | D12: =25.2/0.4 -> 63 | E12: =25.2/0.4 -> 63 | F12: 第五册第一分册S6-3-4
A13: 11 | B13: BK0+087.6 | C13: 马宅互通B辅道桥东阳方向 | D13: =25.2/0.4 -> 63 | E13: =25.2/0.4 -> 63 | F13: 第五册第一分册S6-3-4
A21: 合计： | D21: =SUM(D3:D13) -> 1583.5 | E21: =SUM(E3:E13) -> 1583.5
A22: 计算： 复核： 监理: 日期:

Sheet 303-1-5 厚200mm水泥稳定碎石底基层
A1: 303-1-5 厚200mm水泥稳定碎石底基层数量计算表
A2: 序号 | B2: 段落 | C2: 长度（m） | D2: 被交道路路面宽度（m） | E2: 被交道路路面宽度（m） | F2: 核算数量（m2) | G2: 图纸数量（m2) | H2: 备注
A3: 1 | B3: YK4+622.424 | D3: 6 | E3: 6.5 | F3: 155.5 | G3: 155.5 | H3: 第五册第二分册S6-5-2
A4: 2 | B4: ZK4+662.958 | D4: 6 | E4: 6.5 | F4: 225.9 | G4: 225.9
A21: 合计： | F21: =SUM(F3:F20) -> 381.4 | G21: =SUM(G3:G4) -> 381.4
A22: 计算： 复核： 监理: 日期:

Sheet 303-1-8 厚340mm水泥稳定碎石底基层
A1: 303-1-8 厚340mm水泥稳定土底基层数量计算表
A2: 序号 | B2: 段落 | C2: 长度（m） | D2: 宽度（m） | E2: 核算数量（m2) | F2: 图纸数量（m2) | G2: 备注
A3: 1 | B3: K4+300-K4+800 | C3: =500-256 -> 244 | E3: 3759 | F3: 3759 | G3: 第二册S3-31-1
A4: 2 | B4: K5+980-K6+800 | C4: 820 | E4: 12942 | F4: 12942
A5: 3 | B5: ZK4+300-ZK4+805 | C5: =505-256 -> 249 | E5: 3902 | F5: 3902
A6: 4 | B6: ZK6+016-ZK6+809 | C6: 793 | E6: 12508 | F6: 12508
A7: 5 | B7: 隧道口交叉渡线 | E7: 1722 | F7: 1722
A8: 6 | B8: K6+800-K6+829 | C8: 29 | E8: 453 | F8: 453 | G8: 第五册第一分册S6-3-12 | H8: 右幅
A9: 7 | B9: K7+091-K7+179 | C9: 88.5 | E9: 2245 | F9: 2245 | H9: 右幅
A10: 8 | B10: K7+091-K7+170 | C10: 79.3 | E10: 2147 | F10: 2147 | H10: 左幅
A11: 9 | B11: K7+179-K7+245 | C11: 65.5 | E11: 1023 | F11: 1023 | H11: 右幅
A12: 10 | B12: K7+170-K7+245 | C12: 74.7 | E12: 1165 | F12: 1165 | H12: 左幅
A13: 11 | B13: K7+245-K7+416 | C13: 170.6 | E13: 5179 | F13: 5179 | H13: 全幅
A14: 12 | B14: ZK6+809-ZK6+838 | C14: 29 | E14: 453 | F14: 453 | H14: 左幅
A15: 13 | B15: AK0+121-AK0+195 | C15: 73.9 | E15: 628 | F15: 628
A16: 14 | B16: AK0+195-AK0+231 | C16: 36.1 | E16: 338 | F16: 338
A17: 15 | B17: AK0+231-AK0+357 | C17: 125.9 | E17: 1242 | F17: 1242
A18: 16 | B18: AK0+395-AK0+420 | C18: 25.4 | E18: 250 | F18: 250
A19: 17 | B19: BK0+018-BK0+068 | C19: 50 | E19: 493 | F19: 493
A20: 18 | B20: BK0+106-BK0+315 | C20: 208.4 | E20: 2055 | F20: 2055
A21: 19 | B21: BK0+315-BK0+375 | C21: 60 | E21: 712 | F21: 712
A22: 20 | B22: ck0+027-CK0+255 | C22: 227.6 | E22: 2244 | F22: 2244
A23: 21 | B23: DK0+000-DK0+214 | C23: 213.8 | E23: 2108 | F23: 2108
A24: 22 | B24: 下新线 | E24: 1928 | F24: 1928
A25: 23 | B25: 南下线 | E25: 1641 | F25: 1641
A26: 24 | B26: AK0+461交下新线 | E26: 3162 | F26: 3162 | G26: 第五册第一分册S6-2-9
A27: 25 | B27: CD匝道交南下线 | E27: 2403 | F27: 2403
A28: 合计： | E28: =SUM(E3:E27) -> 66702 | F28: =SUM(F3:F27) -> 66702
A29: 计算： 复核： 监理: 日期:

Sheet 304-1-5 厚200mm 水泥稳定碎石基层 
A1: 304-1-5 厚200mm 水泥稳定碎石基层 数量计算表
A2: 序号 | B2: 段落 | C2: 长度（m） | D2: 宽度（m） | E2: 核算数量（m2) | F2: 图纸数量（m2) | G2: 备注
A3: 1 | B3: K4+300-4+800 | C3: =500-256 -> 244 | D3: 15.28 | E3: =D3*C3 -> 3728.32 | F3: 3688 | G3: 第二册S3-31-1
A4: 2 | B4: K5+980-K6+800 | C4: 820 | D4: 15.28 | E4: =D4*C4 -> 12529.6 | F4: 12697
A5: 3 | B5: ZK4+300-ZK4+805 | C5: =505-256 -> 249 | D5: 15.28 | E5: =D5*C5 -> 3804.72 | F5: 3828
A6: 4 | B6: ZK6+016-ZK6+809 | C6: 793 | D6: 15.28 | E6: =D6*C6 -> 12117.04 | F6: 12271
A7: 5 | B7: 隧道口交叉渡线 | E7: 1711 | F7: 1711
A8: 6 | B8: K6+800-K6+829 | C8: 29 | D8: =14.75+0.28 -> 15.03 | E8: =C8*D8 -> 435.87 | F8: 444 | G8: 第五册第一分册S6-3-12 | H8: 右幅
A9: 7 | B9: K7+091-K7+179 | C9: 88.5 | E9: 2218 | F9: 2218 | H9: 右幅
A10: 8 | B10: K7+091-K7+170 | C10: 79.3 | E10: 2123 | F10: 2123 | H10: 左幅
A11: 9 | B11: K7+179-K7+245 | C11: 65.5 | D11: =14.75+0.28 -> 15.03 | E11: =C11*D11 -> 984.465 | F11: 1003 | H11: 右幅
A12: 10 | B12: K7+170-K7+245 | C12: 74.7 | D12: =14.75+0.28 -> 15.03 | E12: =C12*D12 -> 1122.741 | F12: 1143 | H12: 左幅
A13: 11 | B13: K7+245-K7+416 | C13: 170.6 | D13: =29.5+0.56 -> 30.06 | E13: =C13*D13 -> 5128.236 | F13: 5128 | H13: 全幅
A14: 12 | B14: ZK6+809-ZK6+838 | C14: 29 | D14: =14.75+0.28 -> 15.03 | E14: =C14*D14 -> 435.87 | F14: 444 | H14: 左幅
A15: 13 | B15: AK0+121-AK0+195 | C15: 73.9 | E15: 606 | F15: 606
A16: 14 | B16: AK0+195-AK0+231 | C16: 36.1 | E16: 328 | F16: 328
A17: 15 | B17: AK0+231-AK0+357 | C17: 125.9 | D17: =9+0.56 -> 9.56 | E17: =C17*D17 -> 1203.604 | F17: 1204
A18: 16 | B18: AK0+395-AK0+420 | C18: 25.4 | D18: =9+0.56 -> 9.56 | E18: =C18*D18 -> 242.824 | F18: 243
A19: 17 | B19: BK0+018-BK0+068 | C19: 50 | D19: =9+0.56 -> 9.56 | E19: =C19*D19 -> 478 | F19: 478
A20: 18 | B20: BK0+106-BK0+315 | C20: 208.4 | D20: =9+0.56 -> 9.56 | E20: =C20*D20 -> 1992.304 | F20: 1992
A21: 19 | B21: BK0+315-BK0+375 | C21: 60 | E21: 664 | F21: 694
A22: 20 | B22: ck0+027-CK0+255 | C22: 227.6 | D22: =9+0.56 -> 9.56 | E22: =C22*D22 -> 2175.856 | F22: 2175
A23: 21 | B23: DK0+000-DK0+214 | C23: 213.8 | D23: =9+0.56 -> 9.56 | E23: =C23*D23 -> 2043.928 | F23: 2044
A24: 22 | B24: 下新线 | E24: 1836 | F24: 1836
A25: 23 | B25: 南下线 | E25: 1562 | F25: 1562
A26: 24 | B26: YK4+622.424七秩塘接线 | E26: 154.5 | F26: 154.5 | G26: 第五册第一分册S6-5-2
A27: 25 | B27: ZK4+662.958七秩塘接线 | E27: 3012 | F27: 204.5
A28: 26 | B28: AK0+461交下新线 | E28: 2289 | F28: 3012 | G28: 第五册第一分册S6-2-9
A29: 27 | B29: CD匝道交南下线 | E29: 2180 | F29: 2289
A30: 28 | B30: K4+450改路 | C30: 111 | D30: 6.5 | E30: =C30*D30 -> 721.5 | F30: 722
A31: 29 | B31: K4+620改路 | C31: 406 | D31: 6.5 | E31: =C31*D31 -> 2639 | F31: 2639 | G31: 第七册S9-2-1
A32: 30 | B32: K4+660改路 | C32: 404 | D32: 6.5 | E32: =C32*D32 -> 2626 | F32: 2626
A33: 31 | B33: K6+885改路 | C33: 180 | D33: 7.5 | E33: =C33*D33 -> 1350 | F33: 1350
A34: 32 | B34: K7+060改路 | C34: 240 | D34: 7.5 | E34: =C34*D34 -> 1800 | F34: 1800
A35: 合计： | E35: =SUM(E3:E34) -> 76243.378 | F35: =SUM(F3:F34) -> 74657
A36: 计算： 复核： 监理: 日期:

Sheet 305-2 黏层
A1: 305-2 黏层 数量计算表
A2: 序号 | B2: 段落 | C2: 长度（m） | D2: 宽度（m） | E2: 核算数量（m2) | F2: 图纸数量（m2) | G2: 备注
A3: 1 | B3: K4+456七秩塘桥右幅磐安方向搭板 | C3: 6 | D3: 15 | E3: =D3*C3 -> 90 | F3: 90 | G3: 第二册S3-19
A4: 2 | B4: K4+456七秩塘桥右幅东阳方向搭板 | C4: 8 | D4: 15 | E4: =D4*C4 -> 120 | F4: 121
A5: 3 | B5: ZK4+460.5七秩塘左幅磐安方向搭板 | C5: 8 | D5: 15 | E5: =D5*C5 -> 120 | F5: 121
A6: 4 | B6: ZK4+460.5七秩塘左幅东阳方向搭板 | C6: 6 | D6: 15 | E6: =D6*C6 -> 90 | F6: 90
A7: 5 | B7: K4+300-4+800 | C7: =500-256 -> 244 | D7: 30.14 | E7: =D7*C7 -> 7354.16 | F7: 7.176 | G7: 第二册S3-31-1
A8: 6 | B8: K5+980-K6+800 | C8: 820 | D8: 30.14 | E8: =D8*C8 -> 24714.8 | F8: 24708
A9: 7 | B9: ZK4+300-ZK4+805 | C9: =505-256 -> 249 | D9: 30.14 | E9: =D9*C9 -> 7504.86 | F9: 7449
A10: 8 | B10: ZK6+016-ZK6+809 | C10: 793 | D10: 30.14 | E10: =D10*C10 -> 23901.02 | F10: 23880
A11: 9 | B11: 隧道口交叉渡线 | E11: 3380 | F11: 3380
A12: 10 | B12: K4+800-K5+980 | C12: 1180 | D12: 11.5 | E12: =C12*D12 -> 13570 | F12: 13570 | G12: 第二册S3-31-2 | H12: 后山隧道右幅
A13: 11 | B13: ZK4+805-ZK6+016 | C13: 1211 | D13: 11.5 | E13: =C13*D13 -> 13926.5 | F13: 13927 | H13: 后山隧道左幅
A14: 12 | B14: K4+336-K4+576 | C14: 240 | D14: 15 | E14: =C14*D14 -> 3600 | F14: 3600 | H14: 七秩塘桥右幅
A15: 13 | B15: ZK4+340.5-ZK4+580.5 | C15: 240 | D15: 15 | E15: =C15*D15 -> 3600 | F15: 3600 | H15: 七秩塘桥左幅
A16: 14 | B16: K6+960横路店大桥右幅磐安方向搭板 | C16: 8 | D16: 15 | E16: =C16*D16 -> 120 | F16: 237
A17: 15 | B17: K6+960横路店大桥左幅磐安方向搭板 | C17: 8 | D17: 17.15 | E17: =C17*D17 -> 137.2 | G17: 第五册第一分册S6-3-5
A18: 16 | B18: K6+960横路店大桥右幅东阳方向搭板 | C18: 8 | D18: 19.94 | E18: =C18*D18 -> 159.52 | F18: 314
A19: 17 | B19: K6+960横路店大桥右幅东阳方向搭板 | C19: 8 | D19: 19.785 | E19: =C19*D19 -> 158.28
A20: 18 | B20: K7+711.6马宅大桥磐安方向搭板 | C20: 8 | D20: 32 | E20: =C20*D20 -> 256 | F20: 237
A21: 19 | B21: AK0+376马宅互通A辅道桥磐安方向搭板 | C21: 6 | D21: 9 | E21: =C21*D21 -> 54 | F21: 54
A22: 20 | B22: AK0+376马宅互通A辅道桥东阳方向搭板 | C22: 6 | D22: 9 | E22: =C22*D22 -> 54 | F22: 54
A23: 21 | B23: BK0+087.6马宅互通B辅道桥磐安方向搭板 | C23: 6 | D23: 9 | E23: =C23*D23 -> 54 | F23: 54
A24: 22 | B24: BK0+087.6马宅互通B辅道桥东阳方向搭板 | C24: 6 | D24: 9 | E24: =C24*D24 -> 54 | F24: 54
A25: 23 | B25: K6+800-K6+829 | C25: 29 | D25: =14.79+14.85 -> 29.64 | E25: =C25*D25 -> 859.56 | F25: 868 | G25: 第五册第一分册S6-3-12 | H25: 右幅
A26: 24 | B26: K7+091-K7+179 | C26: 88.5 | E26: 4385 | F26: 4385 | H26: 右幅
A27: 25 | B27: K7+091-K7+170 | C27: 79.3 | E27: 4201 | F27: 4201 | H27: 左幅
A28: 26 | B28: K7+179-K7+245 | C28: 65.5 | D28: =14.79+14.85 -> 29.64 | E28: =C28*D28 -> 1941.42 | F28: 1961 | H28: 右幅
A29: 27 | B29: K7+170-K7+245 | C29: 74.7 | D29: =14.79+14.85 -> 29.64 | E29: =C29*D29 -> 2214.108 | F29: 2234 | H29: 左幅
A30: 28 | B30: K7+245-K7+416 | C30: 170.6 | D30: =29.58+29.7 -> 59.28 | E30: =C30*D30 -> 10113.168 | F30: 10137 | H30: 全幅
A31: 29 | B31: ZK6+809-ZK6+838 | C31: 29 | D31: =14.79+14.85 -> 29.64 | E31: =C31*D31 -> 859.56 | F31: 868 | H31: 左幅
A32: 30 | B32: AK0+121-AK0+195 | C32: 73.9 | E32: 1169 | F32: 1168
A33: 31 | B33: AK0+195-AK0+231 | C33: 36.1 | E33: 634 | F33: 634
A34: 32 | B34: AK0+231-AK0+357 | C34: 125.9 | D34: =9.08+9.2 -> 18.28 | E34: =C34*D34 -> 2301.452 | F34: 2320
A35: 33 | B35: AK0+395-AK0+420 | C35: 25.4 | D35: =9.08+9.2 -> 18.28 | E35: =C35*D35 -> 464.312 | F35: 468
A36: 34 | B36: BK0+018-BK0+068 | C36: 50 | D36: =9.08+9.2 -> 18.28 | E36: =C36*D36 -> 914 | F36: 921
A37: 35 | B37: BK0+106-BK0+315 | C37: 208.4 | D37: =9.08+9.2 -> 18.28 | E37: =C37*D37 -> 3809.552 | F37: 3838
A38: 36 | B38: BK0+315-BK0+375 | C38: 60 | E38: 1354 | F38: 1354
A39: 37 | B39: ck0+027-CK0+255 | C39: 227.6 | D39: =9.08+9.2 -> 18.28 | E39: =C39*D39 -> 4160.528 | F39: 4192
A40: 38 | B40: DK0+000-DK0+214 | C40: 213.8 | D40: =9.08+9.2 -> 18.28 | E40: =C40*D40 -> 3908.264 | F40: 3939
...

Sheet 305-3-6 下封层
A1: 305-3-6 下封层 数量计算表
A2: 序号 | B2: 段落 | C2: 长度（m） | D2: 宽度（m） | E2: 核算数量（m2) | F2: 图纸数量（m2) | G2: 备注
A3: 1 | B3: K4+300-4+800 | C3: =500-256 -> 244 | D3: 15.28 | E3: =D3*C3 -> 3728.32 | F3: 3688 | G3: 第二册S3-31-1
A4: 2 | B4: K5+980-K6+800 | C4: 820 | D4: 15.28 | E4: =D4*C4 -> 12529.6 | F4: 12697
A5: 3 | B5: ZK4+300-ZK4+805 | C5: =505-256 -> 249 | D5: 15.28 | E5: =D5*C5 -> 3804.72 | F5: 3828
A6: 4 | B6: ZK6+016-ZK6+809 | C6: 793 | D6: 15.28 | E6: =D6*C6 -> 12117.04 | F6: 12271
A7: 5 | B7: 隧道口交叉渡线 | E7: 1711 | F7: 1711
A8: 6 | B8: K6+800-K6+829 | C8: 29 | D8: =14.75+0.28 -> 15.03 | E8: =C8*D8 -> 435.87 | F8: 444 | G8: 第五册第一分册S6-3-12 | H8: 右幅
A9: 7 | B9: K7+091-K7+179 | C9: 88.5 | E9: 2218 | F9: 2218 | H9: 右幅
A10: 8 | B10: K7+091-K7+170 | C10: 79.3 | E10: 2123 | F10: 2123 | H10: 左幅
A11: 9 | B11: K7+179-K7+245 | C11: 65.5 | D11: =14.75+0.28 -> 15.03 | E11: =C11*D11 -> 984.465 | F11: 1003 | H11: 右幅
A12: 10 | B12: K7+170-K7+245 | C12: 74.7 | D12: =14.75+0.28 -> 15.03 | E12: =C12*D12 -> 1122.741 | F12: 1143 | H12: 左幅
A13: 11 | B13: K7+245-K7+416 | C13: 170.6 | D13: =29.5+0.56 -> 30.06 | E13: =C13*D13 -> 5128.236 | F13: 5128 | H13: 全幅
A14: 12 | B14: ZK6+809-ZK6+838 | C14: 29 | D14: =14.75+0.28 -> 15.03 | E14: =C14*D14 -> 435.87 | F14: 444 | H14: 左幅
A15: 13 | B15: AK0+121-AK0+195 | C15: 73.9 | E15: 606 | F15: 606
A16: 14 | B16: AK0+195-AK0+231 | C16: 36.1 | E16: 328 | F16: 328
A17: 15 | B17: AK0+231-AK0+357 | C17: 125.9 | D17: =9+0.56 -> 9.56 | E17: =C17*D17 -> 1203.604 | F17: 1204
A18: 16 | B18: AK0+395-AK0+420 | C18: 25.4 | D18: =9+0.56 -> 9.56 | E18: =C18*D18 -> 242.824 | F18: 243
A19: 17 | B19: BK0+018-BK0+068 | C19: 50 | D19: =9+0.56 -> 9.56 | E19: =C19*D19 -> 478 | F19: 478
A20: 18 | B20: BK0+106-BK0+315 | C20: 208.4 | D20: =9+0.56 -> 9.56 | E20: =C20*D20 -> 1992.304 | F20: 1992
A21: 19 | B21: BK0+315-BK0+375 | C21: 60 | E21: 664 | F21: 694
A22: 20 | B22: ck0+027-CK0+255 | C22: 227.6 | D22: =9+0.56 -> 9.56 | E22: =C22*D22 -> 2175.856 | F22: 2175
A23: 21 | B23: DK0+000-DK0+214 | C23: 213.8 | D23: =9+0.56 -> 9.56 | E23: =C23*D23 -> 2043.928 | F23: 2044
A24: 22 | B24: 下新线 | E24: 1836 | F24: 1836
A25: 23 | B25: 南下线 | E25: 1562 | F25: 1562
A26: 24 | B26: YK4+622.424七秩塘接线 | E26: 154.5 | F26: 154.5 | G26: 第五册第一分册S6-5-2
A27: 25 | B27: ZK4+662.958七秩塘接线 | E27: 204.5 | F27: 204.5
A28: 26 | B28: AK0+461交下新线 | E28: 3012 | F28: 3012 | G28: 第五册第一分册S6-2-9
A29: 27 | B29: CD匝道交南下线 | E29: 2289 | F29: 2289
A30: 28 | B30: K4+620改路 | C30: 406 | D30: 6.5 | E30: =C30*D30 -> 2639 | F30: 2639 | G30: 第七册S9-2-1
A31: 29 | B31: K4+660改路 | C31: 404 | D31: 6.5 | E31: =C31*D31 -> 2626 | F31: 2626
A34: 合计： | E34: =SUM(E3:E33) -> 70396.378 | F34: =SUM(F3:F33) -> 70785
A35: 计算： 复核： 监理: 日期:

Sheet 305-5-5 防水黏结层 
A1: 305-5-5 防水黏结层 数量计算表
A2: 序号 | B2: 段落 | C2: 长度（m） | D2: 宽度（m） | E2: 核算数量（m2) | F2: 图纸数量（m2) | G2: 备注
A3: 1 | B3: K4+456七秩塘桥右幅磐安方向搭板 | C3: 6 | D3: =15+0.18 -> 15.18 | E3: =D3*C3 -> 91.08 | F3: 91 | G3: 第二册S3-19
A4: 2 | B4: K4+456七秩塘桥右幅东阳方向搭板 | C4: 8 | D4: =15+0.18 -> 15.18 | E4: =D4*C4 -> 121.44 | F4: 122
A5: 3 | B5: ZK4+460.5七秩塘左幅磐安方向搭板 | C5: 8 | D5: =15+0.18 -> 15.18 | E5: =D5*C5 -> 121.44 | F5: 122
A6: 4 | B6: ZK4+460.5七秩塘左幅东阳方向搭板 | C6: 6 | D6: =15+0.18 -> 15.18 | E6: =D6*C6 -> 91.08 | F6: 91
A7: 5 | B7: K4+800-K5+980 | C7: 1180 | D7: 11.5 | E7: =C7*D7 -> 13570 | F7: 13570 | G7: 第二册S3-31-2 | H7: 后山隧道右幅
A8: 6 | B8: ZK4+805-ZK6+016 | C8: 1211 | D8: 11.5 | E8: =C8*D8 -> 13926.5 | F8: 13927 | H8: 后山隧道左幅
A9: 7 | B9: K4+336-K4+576 | C9: 240 | D9: 15 | E9: =C9*D9 -> 3600 | F9: 3600 | H9: 七秩塘桥右幅
A10: 8 | B10: ZK4+340.5-ZK4+580.5 | C10: 240 | D10: 15 | E10: =C10*D10 -> 3600 | F10: 3600 | H10: 七秩塘桥左幅
A11: 9 | B11: K6+960横路店大桥右幅磐安方向搭板 | C11: 8 | D11: 15.18 | E11: =C11*D11 -> 121.44 | F11: 238
A12: 10 | B12: K6+960横路店大桥左幅磐安方向搭板 | C12: 8 | D12: 17.25 | E12: =C12*D12 -> 138 | G12: 第五册第一分册S6-3-5
A13: 11 | B13: K6+960横路店大桥右幅东阳方向搭板 | C13: 8 | D13: 20.03 | E13: =C13*D13 -> 160.24 | F13: 315
A14: 12 | B14: K6+960横路店大桥右幅东阳方向搭板 | C14: 8 | D14: 19.865 | E14: =C14*D14 -> 158.92
A15: 13 | B15: K7+711.6马宅大桥磐安方向搭板 | C15: 8 | D15: 32.2 | E15: =C15*D15 -> 257.6 | F15: 238
A16: 14 | B16: AK0+376马宅互通A辅道桥磐安方向搭板 | C16: 6 | D16: 9.1 | E16: =C16*D16 -> 54.6 | F16: 55
A17: 15 | B17: AK0+376马宅互通A辅道桥东阳方向搭板 | C17: 6 | D17: 9.1 | E17: =C17*D17 -> 54.6 | F17: 55
A18: 16 | B18: BK0+087.6马宅互通B辅道桥磐安方向搭板 | C18: 6 | D18: 9.1 | E18: =C18*D18 -> 54.6 | F18: 55
A19: 17 | B19: BK0+087.6马宅互通B辅道桥东阳方向搭板 | C19: 6 | D19: 9.1 | E19: =C19*D19 -> 54.6 | F19: 55
A20: 18 | B20: K6+840-K7+080 | C20: 240 | E20: 4192.98 | F20: 4130 | G20: 第五册第一分册S6-3-12 | H20: 横路店大桥右幅
A21: 19 | B21: ZK6+848.6-K7+080 | C21: 240 | E21: 4500.3 | F21: 4436 | H21: 横路店大桥左幅
A22: 20 | B22: K7+426.6-K7+816.6 | C22: 390 | D22: 15 | E22: =C22*D22 -> 5850 | F22: 5753 | H22: 马宅大桥左幅
A23: 21 | B23: K7+426.6-K7+816.6 | C23: 390 | D23: 15 | E23: =C23*D23 -> 5850 | F23: 5753 | H23: 马宅大桥右幅
A24: 22 | B24: AK0+366-AK0+386 | C24: 20 | D24: 9 | E24: =C24*D24 -> 180 | F24: 180 | H24: A辅道桥
A25: 23 | B25: BK0+077.4-BK0+097.4 | C25: 20 | D25: 9 | E25: =C25*D25 -> 180 | F25: 180 | H25: B辅道桥
A28: 合计： | E28: =SUM(E3:E27) -> 56929.42 | F28: =SUM(F3:F27) -> 56566
A29: 计算： 复核： 监理: 日期:

Sheet 305-6-2 抛丸 
A1: 305-6-2 抛丸 数量计算表
A2: 序号 | B2: 段落 | C2: 长度（m） | D2: 宽度（m） | E2: 核算数量（m2) | F2: 图纸数量（m2) | G2: 备注
A3: 1 | B3: K4+800-K5+980 | C3: 1180 | D3: 11.5 | E3: =C3*D3 -> 13570 | F3: 13570 | G3: 第二册S3-31-2 | H3: 后山隧道右幅
A4: 2 | B4: ZK4+805-ZK6+016 | C4: 1211 | D4: 11.5 | E4: =C4*D4 -> 13926.5 | F4: 13927 | H4: 后山隧道左幅
A5: 3 | B5: K4+336-K4+576 | C5: 240 | D5: 15 | E5: =C5*D5 -> 3600 | F5: 3600 | H5: 七秩塘桥右幅
A6: 4 | B6: ZK4+340.5-ZK4+580.5 | C6: 240 | D6: 15 | E6: =C6*D6 -> 3600 | F6: 3600 | H6: 七秩塘桥左幅
A7: 5 | B7: K6+840-K7+080 | C7: 240 | E7: 4192.98 | F7: 4130 | G7: 第五册第一分册S6-3-12 | H7: 横路店大桥右幅
A8: 6 | B8: ZK6+848.6-K7+080 | C8: 240 | E8: 4500.3 | F8: 4436 | H8: 横路店大桥左幅
A9: 7 | B9: K7+426.6-K7+816.6 | C9: 390 | D9: 15 | E9: =C9*D9 -> 5850 | F9: 5753 | H9: 马宅大桥左幅
A10: 8 | B10: K7+426.6-K7+816.6 | C10: 390 | D10: 15 | E10: =C10*D10 -> 5850 | F10: 5753 | H10: 马宅大桥右幅
A11: 9 | B11: AK0+366-AK0+386 | C11: 20 | D11: 9 | E11: =C11*D11 -> 180 | F11: 180 | H11: A辅道桥
A12: 10 | B12: BK0+077.4-BK0+097.4 | C12: 20 | D12: 9 | E12: =C12*D12 -> 180 | F12: 180 | H12: B辅道桥
A15: 合计： | E15: =SUM(E3:E14) -> 55449.78 | F15: =SUM(F3:F14) -> 55129
A16: 计算： 复核： 监理: 日期:

Sheet 306-1-3-4 厚80mm粗粒式沥青混凝土 
A1: 306-1-3-4 厚80mm粗粒式沥青混凝土数量计算表
A2: 序号 | B2: 段落 | C2: 长度（m） | D2: 宽度（m） | E2: 核算数量（m2) | F2: 图纸数量（m2) | G2: 备注
A3: 1 | B3: K4+300-4+800 | C3: =500-256 -> 244 | D3: 15.1 | E3: =D3*C3 -> 3684.4 | F3: 3621 | G3: 第二册S3-31-1
A4: 2 | B4: K5+980-K6+800 | C4: 820 | D4: 15.1 | E4: =D4*C4 -> 12382 | F4: 12468
A5: 3 | B5: ZK4+300-ZK4+805 | C5: =505-256 -> 249 | D5: 15.1 | E5: =D5*C5 -> 3759.9 | F5: 3759
A6: 4 | B6: ZK6+016-ZK6+809 | C6: 793 | D6: 15.1 | E6: =D6*C6 -> 11974.3 | F6: 12050
A7: 5 | B7: 隧道口交叉渡线 | E7: 1690 | F7: 1690
A8: 6 | B8: K6+800-K6+829 | C8: 29 | D8: =14.75+0.18 -> 14.93 | E8: =C8*D8 -> 432.97 | F8: 436 | G8: 第五册第一分册S6-3-12 | H8: 右幅
A9: 7 | B9: K7+091-K7+179 | C9: 88.5 | E9: 2199 | F9: 2199 | H9: 右幅
A10: 8 | B10: K7+091-K7+170 | C10: 79.3 | E10: 2106 | F10: 2106 | H10: 左幅
A11: 9 | B11: K7+179-K7+245 | C11: 65.5 | D11: =14.75+0.18 -> 14.93 | E11: =C11*D11 -> 977.915 | F11: 985 | H11: 右幅
A12: 10 | B12: K7+170-K7+245 | C12: 74.7 | D12: =14.75+0.18 -> 14.93 | E12: =C12*D12 -> 1115.271 | F12: 1122 | H12: 左幅
A13: 11 | B13: K7+245-K7+416 | C13: 170.6 | D13: =29.5+0.36 -> 29.86 | E13: =C13*D13 -> 5094.116 | F13: 5080 | H13: 全幅
A14: 12 | B14: ZK6+809-ZK6+838 | C14: 29 | D14: =14.75+0.18 -> 14.93 | E14: =C14*D14 -> 432.97 | F14: 436 | H14: 左幅
A15: 13 | B15: AK0+121-AK0+195 | C15: 73.9 | E15: 590 | F15: 590
A16: 14 | B16: AK0+195-AK0+231 | C16: 36.1 | E16: 320 | F16: 320
A17: 15 | B17: AK0+231-AK0+357 | C17: 125.9 | D17: =9+0.18 -> 9.18 | E17: =C17*D17 -> 1155.762 | F17: 1169
A18: 16 | B18: AK0+395-AK0+420 | C18: 25.4 | D18: =9+0.18 -> 9.18 | E18: =C18*D18 -> 233.172 | F18: 236
A19: 17 | B19: BK0+018-BK0+068 | C19: 50 | D19: =9+0.18 -> 9.18 | E19: =C19*D19 -> 459 | F19: 464
A20: 18 | B20: BK0+106-BK0+315 | C20: 208.4 | D20: =9+0.18 -> 9.18 | E20: =C20*D20 -> 1913.112 | F20: 1934
A21: 19 | B21: BK0+315-BK0+375 | C21: 60 | E21: 681 | F21: 681
A22: 20 | B22: ck0+027-CK0+255 | C22: 227.6 | D22: =9+0.18 -> 9.18 | E22: =C22*D22 -> 2089.368 | F22: 2112
A23: 21 | B23: DK0+000-DK0+214 | C23: 213.8 | D23: =9+0.18 -> 9.18 | E23: =C23*D23 -> 1962.684 | F23: 1984
A24: 22 | B24: 下新线 | E24: 1749 | F24: 1749
A25: 23 | B25: 南下线 | E25: 1488 | F25: 1488
A28: 合计： | E28: =SUM(E3:E27) -> 58489.94 | F28: =SUM(F3:F27) -> 58679
A29: 计算： 复核： 监理: 日期:

Sheet 306-2-2-3 厚60mm中粒式沥青混凝土
A1: 306-2-2-3 厚60mm中粒式沥青混凝土数量计算表
A2: 序号 | B2: 段落 | C2: 长度（m） | D2: 宽度（m） | E2: 核算数量（m2) | F2: 图纸数量（m2) | G2: 备注
A3: 1 | B3: K4+456七秩塘桥右幅磐安方向搭板 | C3: 6 | D3: =15+0.1 -> 15.1 | E3: =D3*C3 -> 90.6 | F3: 91 | G3: 第二册S3-19
A4: 2 | B4: K4+456七秩塘桥右幅东阳方向搭板 | C4: 8 | D4: =15+0.1 -> 15.1 | E4: =D4*C4 -> 120.8 | F4: 121
A5: 3 | B5: ZK4+460.5七秩塘左幅磐安方向搭板 | C5: 8 | D5: =15+0.1 -> 15.1 | E5: =D5*C5 -> 120.8 | F5: 121
A6: 4 | B6: ZK4+460.5七秩塘左幅东阳方向搭板 | C6: 6 | D6: =15+0.1 -> 15.1 | E6: =D6*C6 -> 90.6 | F6: 91
A7: 5 | B7: K4+300-4+800 | C7: =500-256 -> 244 | D7: 15.1 | E7: =D7*C7 -> 3684.4 | F7: 3588 | G7: 第二册S3-31-1
A8: 6 | B8: K5+980-K6+800 | C8: 820 | D8: 15.1 | E8: =D8*C8 -> 12382 | F8: 12354
A9: 7 | B9: ZK4+300-ZK4+805 | C9: =505-256 -> 249 | D9: 15.1 | E9: =D9*C9 -> 3759.9 | F9: 3724
A10: 8 | B10: ZK6+016-ZK6+809 | C10: 793 | D10: 15.1 | E10: =D10*C10 -> 11974.3 | F10: 11940
A11: 9 | B11: 隧道口交叉渡线 | E11: 1690 | F11: 1690
A12: 10 | B12: K4+800-K5+980 | C12: 1180 | D12: 11.5 | E12: =C12*D12 -> 13570 | F12: 13570 | G12: 第二册S3-31-2 | H12: 后山隧道右幅
A13: 11 | B13: ZK4+805-ZK6+016 | C13: 1211 | D13: 11.5 | E13: =C13*D13 -> 13926.5 | F13: 13927 | H13: 后山隧道左幅
A14: 12 | B14: K4+336-K4+576 | C14: 240 | D14: 15 | E14: =C14*D14 -> 3600 | F14: 3600 | H14: 七秩塘桥右幅
A15: 13 | B15: ZK4+340.5-ZK4+580.5 | C15: 240 | D15: 15 | E15: =C15*D15 -> 3600 | F15: 3600 | H15: 七秩塘桥左幅
A16: 14 | B16: K6+960横路店大桥右幅磐安方向搭板 | C16: 8 | D16: 15.1 | E16: =C16*D16 -> 120.8 | F16: 237
A17: 15 | B17: K6+960横路店大桥左幅磐安方向搭板 | C17: 8 | D17: 17.25 | E17: =C17*D17 -> 138 | G17: 第五册第一分册S6-3-5
A18: 16 | B18: K6+960横路店大桥右幅东阳方向搭板 | C18: 8 | D18: 20.03 | E18: =C18*D18 -> 160.24 | F18: 315
A19: 17 | B19: K6+960横路店大桥右幅东阳方向搭板 | C19: 8 | D19: 19.865 | E19: =C19*D19 -> 158.92
A20: 18 | B20: K7+711.6马宅大桥磐安方向搭板 | C20: 8 | D20: 32.2 | E20: =C20*D20 -> 257.6 | F20: 237
A21: 19 | B21: AK0+376马宅互通A辅道桥磐安方向搭板 | C21: 6 | D21: 9.1 | E21: =C21*D21 -> 54.6 | F21: 55
A22: 20 | B22: AK0+376马宅互通A辅道桥东阳方向搭板 | C22: 6 | D22: 9.1 | E22: =C22*D22 -> 54.6 | F22: 55
A23: 21 | B23: BK0+087.6马宅互通B辅道桥磐安方向搭板 | C23: 6 | D23: 9.1 | E23: =C23*D23 -> 54.6 | F23: 55
A24: 22 | B24: BK0+087.6马宅互通B辅道桥东阳方向搭板 | C24: 6 | D24: 9.1 | E24: =C24*D24 -> 54.6 | F24: 55
A25: 23 | B25: K6+800-K6+829 | C25: 29 | D25: 14.85 | E25: =C25*D25 -> 430.65 | F25: 432 | G25: 第五册第一分册S6-3-12 | H25: 右幅
A26: 24 | B26: K7+091-K7+179 | C26: 88.5 | E26: 2186 | F26: 2186 | H26: 右幅
A27: 25 | B27: K7+091-K7+170 | C27: 79.3 | E27: 2095 | F27: 2095 | H27: 左幅
A28: 26 | B28: K7+179-K7+245 | C28: 65.5 | D28: 14.85 | E28: =C28*D28 -> 972.675 | F28: 976 | H28: 右幅
A29: 27 | B29: K7+170-K7+245 | C29: 74.7 | D29: 14.85 | E29: =C29*D29 -> 1109.295 | F29: 1112 | H29: 左幅
A30: 28 | B30: K7+245-K7+416 | C30: 170.6 | D30: 29.7 | E30: =C30*D30 -> 5066.82 | F30: 5057 | H30: 全幅
A31: 29 | B31: ZK6+809-ZK6+838 | C31: 29 | D31: 14.85 | E31: =C31*D31 -> 430.65 | F31: 432 | H31: 左幅
A32: 30 | B32: AK0+121-AK0+195 | C32: 73.9 | E32: 579 | F32: 579
A33: 31 | B33: AK0+195-AK0+231 | C33: 36.1 | E33: 315 | F33: 315
A34: 32 | B34: AK0+231-AK0+357 | C34: 125.9 | D34: 9.1 | E34: =C34*D34 -> 1145.69 | F34: 1151
A35: 33 | B35: AK0+395-AK0+420 | C35: 25.4 | D35: 9.1 | E35: =C35*D35 -> 231.14 | F35: 231
A36: 34 | B36: BK0+018-BK0+068 | C36: 50 | D36: 9.1 | E36: =C36*D36 -> 455 | F36: 457
A37: 35 | B37: BK0+106-BK0+315 | C37: 208.4 | D37: 9.1 | E37: =C37*D37 -> 1896.44 | F37: 1905
A38: 36 | B38: BK0+315-BK0+375 | C38: 60 | E38: 673 | F38: 673
A39: 37 | B39: ck0+027-CK0+255 | C39: 227.6 | D39: 9.1 | E39: =C39*D39 -> 2071.16 | F39: 2080
A40: 38 | B40: DK0+000-DK0+214 | C40: 213.8 | D40: 9.1 | E40: =C40*D40 -> 1945.58 | F40: 1954
...

Sheet 306-2-2-5 厚140mm中粒式沥青混凝土 
A1: 306-2-2-5 厚140mm中粒式沥青混凝土 数量计算表
A2: 序号 | B2: 段落 | C2: 长度（m） | D2: 宽度（m） | E2: 核算数量（m2) | F2: 图纸数量（m2) | G2: 备注
A3: 1 | B3: AK0+461交下新线 | E3: 2868 | F3: 2868 | G3: 第五册第一分册S6-2-9
A4: 2 | B4: CD匝道交南下线 | E4: 2180 | F4: 2180
A21: 合计： | E21: =SUM(E3:E17) -> 5048 | F21: =SUM(F3:F17) -> 5048
A22: 计算： 复核： 监理: 日期:

Sheet 306-3-1-2 厚40mm细粒式沥青玛蹄脂碎石混合料面层
A1: 306-3-1-2 厚40mm细粒式沥青玛蹄脂碎石混合料面层数量计算表
A2: 序号 | B2: 段落 | C2: 长度（m） | D2: 宽度（m） | E2: 核算数量（m2) | F2: 图纸数量（m2) | G2: 备注
A3: 1 | B3: K4+456七秩塘桥右幅磐安方向搭板 | C3: 6 | D3: 15 | E3: =D3*C3 -> 90 | F3: 90 | G3: 第二册S3-19
A4: 2 | B4: K4+456七秩塘桥右幅东阳方向搭板 | C4: 8 | D4: 15 | E4: =D4*C4 -> 120 | F4: 120
A5: 3 | B5: ZK4+460.5七秩塘左幅磐安方向搭板 | C5: 8 | D5: 15 | E5: =D5*C5 -> 120 | F5: 120
A6: 4 | B6: ZK4+460.5七秩塘左幅东阳方向搭板 | C6: 6 | D6: 15 | E6: =D6*C6 -> 90 | F6: 90
A7: 5 | B7: K4+300-4+800 | C7: =500-256 -> 244 | D7: 15 | E7: =D7*C7 -> 3660 | F7: 3564 | G7: 第二册S3-31-1
A8: 6 | B8: K5+980-K6+800 | C8: 820 | D8: 15 | E8: =D8*C8 -> 12300 | F8: 12273
A9: 7 | B9: ZK4+300-ZK4+805 | C9: =505-256 -> 249 | D9: 15 | E9: =D9*C9 -> 3735 | F9: 3700
A10: 8 | B10: ZK6+016-ZK6+809 | C10: 793 | D10: 15 | E10: =D10*C10 -> 11895 | F10: 11861
A11: 9 | B11: 隧道口交叉渡线 | E11: 1690 | F11: 1690
A12: 10 | B12: K4+800-K5+980 | C12: 1180 | D12: 11.5 | E12: =C12*D12 -> 13570 | F12: 13570 | G12: 第二册S3-31-2 | H12: 后山隧道右幅
A13: 11 | B13: ZK4+805-ZK6+016 | C13: 1211 | D13: 11.5 | E13: =C13*D13 -> 13926.5 | F13: 13927 | H13: 后山隧道左幅
A14: 12 | B14: K4+336-K4+576 | C14: 240 | D14: 15 | E14: =C14*D14 -> 3600 | F14: 3600 | H14: 七秩塘桥右幅
A15: 13 | B15: ZK4+340.5-ZK4+580.5 | C15: 240 | D15: 15 | E15: =C15*D15 -> 3600 | F15: 3600 | H15: 七秩塘桥左幅
A16: 14 | B16: K6+960横路店大桥右幅磐安方向搭板 | C16: 8 | D16: 15 | E16: =C16*D16 -> 120 | F16: 236
B17: K6+960横路店大桥左幅磐安方向搭板 | C17: 8 | D17: 17.15 | E17: =C17*D17 -> 137.2 | G17: 第五册第一分册S6-3-5
A18: 16 | B18: K6+960横路店大桥右幅东阳方向搭板 | C18: 8 | D18: 19.94 | E18: =C18*D18 -> 159.52 | F18: 314
B19: K6+960横路店大桥右幅东阳方向搭板 | C19: 8 | D19: 19.785 | E19: =C19*D19 -> 158.28
A20: 18 | B20: K7+711.6马宅大桥磐安方向搭板 | C20: 8 | D20: 32 | E20: =C20*D20 -> 256 | F20: 236
A21: 19 | B21: AK0+376马宅互通A辅道桥磐安方向搭板 | C21: 6 | D21: 9 | E21: =C21*D21 -> 54 | F21: 54
A22: 20 | B22: AK0+376马宅互通A辅道桥东阳方向搭板 | C22: 6 | D22: 9 | E22: =C22*D22 -> 54 | F22: 54
A23: 21 | B23: BK0+087.6马宅互通B辅道桥磐安方向搭板 | C23: 6 | D23: 9 | E23: =C23*D23 -> 54 | F23: 54
A24: 22 | B24: BK0+087.6马宅互通B辅道桥东阳方向搭板 | C24: 6 | D24: 9 | E24: =C24*D24 -> 54 | F24: 54
A25: 23 | B25: K6+800-K6+829 | C25: 29 | D25: 14.75 | E25: =C25*D25 -> 427.75 | F25: 429 | G25: 第五册第一分册S6-3-12 | H25: 右幅
A26: 24 | B26: K7+091-K7+179 | C26: 88.5 | E26: 2174 | F26: 2174 | H26: 右幅
A27: 25 | B27: K7+091-K7+170 | C27: 79.3 | E27: 2084 | F27: 2084 | H27: 左幅
A28: 26 | B28: K7+179-K7+245 | C28: 65.5 | D28: 14.75 | E28: =C28*D28 -> 966.125 | F28: 969 | H28: 右幅
A29: 27 | B29: K7+170-K7+245 | C29: 74.7 | D29: 14.75 | E29: =C29*D29 -> 1101.825 | F29: 1104 | H29: 左幅
A30: 28 | B30: K7+245-K7+416 | C30: 170.6 | D30: 29.5 | E30: =C30*D30 -> 5032.7 | F30: 5040 | H30: 全幅
A31: 29 | B31: ZK6+809-ZK6+838 | C31: 29 | D31: 14.75 | E31: =C31*D31 -> 427.75 | F31: 429 | H31: 左幅
A32: 30 | B32: AK0+121-AK0+195 | C32: 73.9 | E32: 569 | F32: 569
A33: 31 | B33: AK0+195-AK0+231 | C33: 36.1 | E33: 310 | F33: 310
A34: 32 | B34: AK0+231-AK0+357 | C34: 125.9 | D34: 9 | E34: =C34*D34 -> 1133.1 | F34: 1139
A35: 33 | B35: AK0+395-AK0+420 | C35: 25.4 | D35: 9 | E35: =C35*D35 -> 228.6 | F35: 230
A36: 34 | B36: BK0+018-BK0+068 | C36: 50 | D36: 9 | E36: =C36*D36 -> 450 | F36: 452
A37: 35 | B37: BK0+106-BK0+315 | C37: 208.4 | D37: 9 | E37: =C37*D37 -> 1875.6 | F37: 1884
A38: 36 | B38: BK0+315-BK0+375 | C38: 60 | E38: 664 | F38: 664
A39: 37 | B39: ck0+027-CK0+255 | C39: 227.6 | D39: 9 | E39: =C39*D39 -> 2048.4 | F39: 2057
A40: 38 | B40: DK0+000-DK0+214 | C40: 213.8 | D40: 9 | E40: =C40*D40 -> 1924.2 | F40: 1933
...

Sheet 307-1-1 C30混凝土水泥混凝土面层
A1: 307-1-1 C30混凝土水泥混凝土面层数量计算表
A2: 序号 | B2: 段落 | C2: 长度（m） | D2: 宽度（m） | E2: 厚度（m） | F2: 核算数量（m3) | G2: 图纸数量（m3) | H2: 备注
A3: 1 | B3: K4+450 | C3: 111 | D3: 6 | E3: 0.18 | F3: =D3*C3*E3 -> 119.88 | G3: 119.88 | H3: 第七册S9-2-1
A4: 2 | B4: K6+885 | C4: 180 | D4: 7 | E4: 0.18 | F4: =D4*C4*E4 -> 226.8 | G4: 226.8
A5: 3 | B5: K7+060 | C5: 240 | D5: 7 | E5: 0.18 | F5: =D5*C5*E5 -> 302.4 | G5: 302.4
A21: 合计： | F21: =SUM(F3:F17) -> 649.08 | G21: =SUM(G3:G17) -> 649.08
A22: 计算： 复核： 监理: 日期:

Sheet 307-1-2 C35混凝土水泥混凝土面层 
A1: 307-1-2 C35混凝土水泥混凝土面层 数量计算表
A2: 序号 | B2: 段落 | C2: 位置 | D2: 核算数量（m3) | E2: 图纸数量（m3) | F2: 备注
A3: 1 | B3: K4+456 | C3: 七秩塘桥右幅磐安方向水泥砼过渡板 | D3: 16.8 | E3: 16.8 | F3: 第二册S3-17
A4: 2 | B4: K4+456 | C4: 七秩塘桥右幅东阳方向水泥砼过渡板 | D4: 20.8 | E4: 20.8 | F4: 第二册S3-17
A5: 3 | B5: ZK4+460.5 | C5: 七秩塘桥左幅磐安方向水泥砼过渡板 | D5: 20.8 | E5: 20.8 | F5: 第二册S3-17
A6: 4 | B6: ZK4+460.5 | C6: 七秩塘桥左幅东阳方向水泥砼过渡板 | D6: 16.8 | E6: 16.8 | F6: 第二册S3-17
A7: 5 | B7: K6+960 | C7: 横路店大桥磐安方向水泥砼过渡板 | D7: 41.6 | E7: 41.6 | F7: 第五册第一分册S6-3-4
A8: 6 | B8: K6+960 | C8: 横路店大桥东阳方向水泥砼过渡板 | D8: 53.8 | E8: 53.8 | F8: 第五册第一分册S6-3-4
A9: 7 | B9: K7+711.6 | C9: 马宅大桥磐安方向水泥砼过渡板 | D9: 41.6 | E9: 41.6 | F9: 第五册第一分册S6-3-4
A10: 8 | B10: AK0+376 | C10: 马宅互通A辅道桥磐安方向水泥砼过渡板 | D10: 10.7 | E10: 10.7 | F10: 第五册第一分册S6-3-4
A11: 9 | B11: AK0+376 | C11: 马宅互通A辅道桥东阳方向水泥砼过渡板 | D11: 10.7 | E11: 10.7 | F11: 第五册第一分册S6-3-4
A12: 10 | B12: BK0+087.6 | C12: 马宅互通B辅道桥磐安方向水泥砼过渡板 | D12: 10.7 | E12: 10.7 | F12: 第五册第一分册S6-3-4
A13: 11 | B13: BK0+087.6 | C13: 马宅互通B辅道桥东阳方向水泥砼过渡板 | D13: 10.7 | E13: 10.7 | F13: 第五册第一分册S6-3-4
A21: 合计： | D21: =SUM(D3:D17) -> 255 | E21: =SUM(E3:E17) -> 255
A22: 计算： 复核： 监理: 日期:

Sheet 307-1-3 C25混凝土水泥混凝土面层
A1: 307-1-3 C25混凝土水泥混凝土面层数量计算表
A2: 序号 | B2: 段落 | C2: 长度（m） | D2: 宽度（m） | E2: 厚度（m） | F2: 核算数量（m3) | G2: 图纸数量（m3) | H2: 备注
A3: 1 | B3: 双徐线、村道 | C3: 4000 | D3: 6 | E3: 0.2 | F3: =D3*C3*E3 -> 4800 | G3: 4800 | H3: 第七册S9-2-3
A21: 合计： | F21: =SUM(F3:F17) -> 4800 | G21: =SUM(G3:G17) -> 4800
A22: 计算： 复核： 监理: 日期:

Sheet 307-2-2 带肋钢筋 
A1: 307-2-2 带肋钢筋 数量计算表
A2: 序号 | B2: 段落 | C2: 位置 | D2: 核算数量（m3) | E2: 图纸数量（m3) | F2: 备注
A3: 1 | B3: K4+456 | C3: 七秩塘桥右幅磐安方向水泥砼过渡板 | D3: =15.2+111.2 -> 126.4 | E3: =15.2+111.2 -> 126.4 | F3: 第二册S3-17
A4: 2 | B4: K4+456 | C4: 七秩塘桥右幅东阳方向水泥砼过渡板 | D4: =15.2+111.2 -> 126.4 | E4: =15.2+111.2 -> 126.4 | F4: 第二册S3-17
A5: 3 | B5: ZK4+460.5 | C5: 七秩塘桥左幅磐安方向水泥砼过渡板 | D5: =15.2+111.2 -> 126.4 | E5: =15.2+111.2 -> 126.4 | F5: 第二册S3-17
A6: 4 | B6: ZK4+460.5 | C6: 七秩塘桥左幅东阳方向水泥砼过渡板 | D6: =15.2+111.2 -> 126.4 | E6: =15.2+111.2 -> 126.4 | F6: 第二册S3-17
A7: 5 | B7: K6+960 | C7: 横路店大桥磐安方向水泥砼过渡板 | D7: =15.2+222.3 -> 237.5 | E7: =15.2+222.3 -> 237.5 | F7: 第五册第一分册S6-3-4
A8: 6 | B8: K6+960 | C8: 横路店大桥东阳方向水泥砼过渡板 | D8: =15.2+287.7 -> 302.9 | E8: =15.2+287.7 -> 302.9 | F8: 第五册第一分册S6-3-4
A9: 7 | B9: K7+711.6 | C9: 马宅大桥磐安方向水泥砼过渡板 | D9: =15.2+222.3 -> 237.5 | E9: =15.2+222.3 -> 237.5 | F9: 第五册第一分册S6-3-4
A10: 8 | B10: AK0+376 | C10: 马宅互通A辅道桥磐安方向水泥砼过渡板 | D10: =15.2+70.7 -> 85.9 | E10: =15.2+70.7 -> 85.9 | F10: 第五册第一分册S6-3-4
A11: 9 | B11: AK0+376 | C11: 马宅互通A辅道桥东阳方向水泥砼过渡板 | D11: =15.2+70.7 -> 85.9 | E11: =15.2+70.7 -> 85.9 | F11: 第五册第一分册S6-3-4
A12: 10 | B12: BK0+087.6 | C12: 马宅互通B辅道桥磐安方向水泥砼过渡板 | D12: =15.2+70.7 -> 85.9 | E12: =15.2+70.7 -> 85.9 | F12: 第五册第一分册S6-3-4
A13: 11 | B13: BK0+087.6 | C13: 马宅互通B辅道桥东阳方向水泥砼过渡板 | D13: =15.2+70.7 -> 85.9 | E13: =15.2+70.7 -> 85.9 | F13: 第五册第一分册S6-3-4
A21: 合计： | D21: =SUM(D3:D17) -> 1627.1 | E21: =SUM(E3:E17) -> 1627.1
A22: 计算： 复核： 监理: 日期:

Sheet 309-1 路肩培土
A1: 309-1 路肩培土 数量计算表
A2: 序号 | B2: 段落 | C2: 长度 | E2: 核算数量（m3) | F2: 图纸数量（m3) | G2: 备注
C3: 左侧（m） | D3: 右侧（m）
A4: 1 | B4: K4+300-K4+316 | D4: 16 | E4: 6.2 | F4: 6.2 | G4: 第二册PS2-4 | H4: 挖
A5: 2 | B5: K4+316-K4+331 | D5: 15 | E5: 6.7 | F5: 6.7 | H5: 填
A6: 3 | B6: K4+581-K4+760 | D6: 179 | E6: 79.4 | F6: 79.4 | H6: 填
A7: 4 | B7: K4+760-K4+780 | D7: 20 | E7: 7.7 | F7: 7.7 | H7: 挖
A8: 5 | B8: K5+980-K6+180 | D8: 200 | E8: 77 | F8: 77 | H8: 挖
A9: 6 | B9: K6+180-K6+517 | D9: 337 | E9: 149.5 | F9: 149.5 | H9: 填
A10: 7 | B10: K6+517-K6+680 | D10: 163 | E10: 62.7 | F10: 62.7 | H10: 挖
A11: 8 | B11: K6+680-K6+800 | D11: 120 | E11: 53.2 | F11: 53.2 | H11: 填
A12: 9 | B12: K4+300-K4+331 | C12: 31 | E12: 13.8 | F12: 13.8 | H12: 填
A13: 10 | B13: K4+581-K4+780 | C13: 199 | E13: 76.6 | F13: 76.6 | H13: 挖
A14: 11 | B14: K5+980-K6+037 | C14: 57 | E14: 21.9 | F14: 21.9 | H14: 挖
A15: 12 | B15: ZK4+300-ZK4+331 | D15: 31 | E15: 11.9 | F15: 11.9 | H15: 挖
A16: 13 | B16: ZK4+722-ZK4+785 | D16: 63 | E16: 24.2 | F16: 24.2 | H16: 挖
A17: 14 | B17: ZK6+016-ZK6+048 | D17: 32 | E17: 12.3 | F17: 12.3 | H17: 挖
A18: 15 | B18: ZK4+300-ZK4+331 | C18: 31 | E18: 13.8 | F18: 13.8 | H18: 填
A19: 16 | B19: ZK4+586-ZK4+700 | C19: 114 | E19: 50.6 | F19: 50.6 | H19: 填
A20: 17 | B20: ZK4+700-ZK4+785 | C20: 85 | E20: 32.7 | F20: 32.7 | H20: 挖
A21: 18 | B21: ZK6+016-ZK6+280 | C21: 264 | E21: 101.6 | F21: 101.6 | H21: 挖
A22: 19 | B22: ZK6+280-ZK6+510 | C22: 230 | E22: 102 | F22: 102 | H22: 填
A23: 20 | B23: ZK6+510-ZK6+756 | C23: 246 | E23: 94.7 | F23: 94.7 | H23: 挖
A24: 21 | B24: ZK6+756-ZK6+809 | C24: 53 | E24: 23.5 | F24: 23.5 | H24: 填
A25: 22 | B25: K6+800-K6+840 | C25: 40 | D25: 40 | E25: 35.5 | F25: 35.5 | H25: 填
A26: 23 | B26: K6+800-K6+840 | C26: 40 | E26: 57.6 | F26: 57.6
A27: 24 | B27: K7+080-K7+179 | D27: 99 | E27: 44.1 | F27: 44.1 | H27: 填
A28: 25 | B28: K7+080-K7+170 | C28: 90 | E28: 40.1 | F28: 40.1 | H28: 填
A29: 26 | B29: K7+179-K7+427 | D29: 248 | E29: 109.8 | F29: 109.8 | H29: 填
A30: 27 | B30: K7+171-K7+427 | C30: 256 | E30: 113.4 | F30: 113.4 | H30: 填
A31: 28 | B31: K7+080-k7+427 | C31: 347 | E31: 499.1 | F31: 499.1
A32: 29 | B32: AK0+121-AK0+200 | C32: 79 | D32: 79 | E32: 70 | F32: 70 | H32: 填
A33: 30 | B33: AK0+200-AK0+366 | C33: 166 | D33: 166 | E33: 127.8 | F33: 127.8 | H33: 挖
A34: 31 | B34: AK0+386-AK0+461 | C34: 75 | D34: 75 | E34: 66.6 | F34: 66.6 | H34: 填
A35: 32 | B35: BK0+000-BK0+077 | C35: 77 | D35: 77 | E35: 68.7 | F35: 68.7 | H35: 填
A36: 33 | B36: BK0+097-BK0+117 | C36: 20 | D36: 20 | E36: 17.4 | F36: 17.4 | H36: 填
A37: 34 | B37: BK0+117-BK0+320 | C37: 203 | D37: 203 | E37: 156.2 | F37: 156.2 | H37: 挖
A38: 35 | B38: BK0+117-BK0+375 | C38: 258 | D38: 258 | E38: 228.7 | F38: 228.7 | H38: 填
A39: 36 | B39: CK0+000-CK0+255 | C39: 255 | D39: 255 | E39: 225.9 | F39: 225.9 | H39: 填
A40: 37 | B40: DK0+000-DK0+246 | C40: 245 | D40: 245 | E40: 217.8 | F40: 217.8 | H40: 填
...

Sheet 309-4-2-3 C30混凝土预制砼平石
A1: 309-4-2-3 C30混凝土预制砼平石数量计算表
A2: 序号 | B2: 段落 | C2: 核算数量（m) | D2: 图纸数量（m) | E2: 备注
A3: 1 | B3: K4+300-K4+800 | C3: 93 | D3: 93 | E3: 第二册S3-31-1
A4: 2 | B4: K5+980-K6+800 | C4: 722 | D4: 722 | E4: 第二册S3-31-1
A5: 3 | B5: ZK4+300-ZK4+805 | C5: 93 | D5: 93 | E5: 第二册S3-31-1
A6: 4 | B6: ZK6+016-ZK6+809 | C6: 722 | D6: 722 | E6: 第二册S3-31-1
A7: 5 | B7: 隧道口交叉渡线 | C7: 83 | D7: 83 | E7: 第二册S3-31-1
A8: 6 | B8: K6+800-K6+829 | C8: 29 | D8: 29 | E8: 第五册第一分册S6-3-12 | F8: 右幅
A9: 7 | B9: K7+091-K7+179 | C9: 88 | D9: 88 | E9: 第五册第一分册S6-3-12 | F9: 右幅
A10: 8 | B10: K7+091-K7+170 | C10: 79 | D10: 79 | E10: 第五册第一分册S6-3-12 | F10: 左幅
A11: 9 | B11: K7+179-K7+245 | C11: 66 | D11: 66 | E11: 第五册第一分册S6-3-12 | F11: 右幅
A12: 10 | B12: K7+170-K7+245 | C12: 75 | D12: 75 | E12: 第五册第一分册S6-3-12 | F12: 左幅
A13: 11 | B13: K7+245-K7+416 | C13: 341 | D13: 341 | E13: 第五册第一分册S6-3-12 | F13: 全幅
A14: 12 | B14: ZK6+809-ZK6+838 | C14: 29 | D14: 29 | E14: 第五册第一分册S6-3-12 | F14: 左幅
A15: 13 | B15: CK0+027-CK0+255 | C15: 255 | D15: 255 | E15: 第五册第一分册S6-3-12
A16: 14 | B16: DK0+000-DK0+214 | C16: 250 | D16: 250 | E16: 第五册第一分册S6-3-12
A21: 合计： | C21: =SUM(C3:C20) -> 2925 | D21: =SUM(D3:D20) -> 2925
A22: 计算： 复核： 监理: 日期:

Sheet 310-1-1-2 D300mm混凝土排水管 
A1: 310-1-1-2 D300mm混凝土排水管 数量计算表
A2: 序号 | B2: 段落 | C2: 核算数量（m) | D2: 图纸数量（m) | E2: 备注
A3: 1 | B3: K6+350 | C3: 21 | D3: 21 | E3: 第二册PS2-5
A4: 2 | B4: K6+400 | C4: 20 | D4: 20
A5: 3 | B5: K6+450 | C5: 20 | D5: 20
A6: 4 | B6: K6+515 | C6: 20 | D6: 20
A7: 5 | B7: K6+685 | C7: 20 | D7: 20
A8: 6 | B8: K6+765 | C8: 20 | D8: 20
A9: 7 | B9: K7+170 | C9: 26 | D9: 26
A10: 8 | B10: K7+230 | C10: 17 | D10: 17
A11: 9 | B11: K7+280 | C11: 17 | D11: 17
A12: 10 | B12: K7+345 | C12: 17 | D12: 17
A21: 合计： | C21: =SUM(C3:C20) -> 198 | D21: =SUM(D3:D20) -> 198
A22: 计算： 复核： 监理: 日期:

Sheet 310-1-2-4 D110mmPVC排水管 
A1: 310-1-2-4 D110mmPVC排水管 数量计算表
A2: 序号 | B2: 段落 | C2: 核算数量（m) | D2: 图纸数量（m) | E2: 备注
A3: 1 | B3: K4+581-K4+717 | C3: 37 | D3: 37 | E3: 第二册PS2-4
A4: 2 | B4: K6+037-K6+710 | C4: 280 | D4: 280 | E4: 第二册PS2-4
A5: 3 | B5: K6+170-6+800 | C5: 17 | D5: 17 | E5: 第二册PS2-4
A6: 4 | B6: K6+800-K6+840 | C6: 17 | D6: 17 | E6: 第二册PS2-4
A7: 5 | B7: K7+080-K7+427 | C7: 17 | D7: 17 | E7: 第二册PS2-4
A8: 6
A9: 7
A10: 8
A21: 合计： | C21: =SUM(C3:C20) -> 368 | D21: =SUM(D3:D20) -> 368
A22: 计算： 复核： 监理: 日期:

Sheet 310-2-2-1 D300Ⅱ级钢筋砼雨水管
A1: 310-2-2-1 D300Ⅱ级钢筋砼雨水管 数量计算表
A2: 序号 | B2: 段落 | C2: 核算数量（m) | D2: 图纸数量（m) | E2: 备注
A3: 1 | B3: 雨水口连接管 | C3: 174 | D3: 174 | E3: 第二册PS3-5-1
A4: 2
A5: 3
A6: 4
A7: 5
A8: 6
A9: 7
A10: 8
A21: 合计： | C21: =SUM(C3:C20) -> 174 | D21: =SUM(D3:D20) -> 174
A22: 计算： 复核： 监理: 日期:

Sheet 310-2-2-2 D600Ⅱ级钢筋砼雨水管
A1: 310-2-2-2 D600Ⅱ级钢筋砼雨水管 数量计算表
A2: 序号 | B2: 段落 | C2: 核算数量（m) | D2: 图纸数量（m) | E2: 备注
A3: 1 | B3: Y5-Y6 | C3: 32 | D3: 32 | E3: 第二册PS3-1 第二册PS3-3 第二册PS3-5-1
A4: 2 | B4: Y6-Y7 | C4: 32 | D4: 32
A5: 3 | B5: Y7-Y8 | C5: 32 | D5: 32
A6: 4 | B6: Y8-Y9 | C6: 32 | D6: 32
A7: 5 | B7: Y9-Y10 | C7: 32 | D7: 32
A8: 6 | B8: Y10-Y11 | C8: 32 | D8: 32
A9: 7 | B9: Y11-Y12 | C9: 28 | D9: 28
A10: 8 | B10: Y5-Y13 | C10: 26.61 | D10: 26.61
A11: 9 | B11: Y13-Y14 | C11: 31.91 | D11: 31.91
A12: 10 | B12: Y14-Y15 | C12: 32 | D12: 32
A13: 11 | B13: Y15-Y16 | C13: 32 | D13: 32
A14: 12 | B14: Y16-Y17 | C14: 32 | D14: 32
A15: 13 | B15: Y17-Y18 | C15: 32 | D15: 32
... A17: 15 | B17: Y19-Y20 | C17: 28 | D17: 28
A21: 合计： | C21: =SUM(C3:C20) -> 466.52 | D21: =SUM(D3:D20) -> 466.52
A22: 计算： 复核： 监理: 日期:

Sheet 310-2-2-3 D800Ⅱ级钢筋砼雨水管
A1: 310-2-2-3 D800Ⅱ级钢筋砼雨水管 数量计算表
A2: 序号 | B2: 段落 | C2: 核算数量（m) | D2: 图纸数量（m) | E2: 备注
A3: 1 | B3: Y1-Y2 | C3: 8 | D3: 8 | E3: 第二册PS3-1 第二册PS3-3 第二册PS3-5-1
A4: 2 | B4: Y2-Y3 | C4: 32.01 | D4: 32.01
A5: 3 | B5: Y3-Y4 | C5: 32 | D5: 32
A6: 4 | B6: Y4-Y5 | C6: 28 | D6: 28
A7: 5
A8: 6
A9: 7
A10: 8
A21: 合计： | C21: =SUM(C3:C20) -> 100.01 | D21: =SUM(D3:D20) -> 100.01
A22: 计算： 复核： 监理: 日期:

Sheet 310-2-3-2 球墨铸铁给水管（DN200)
A1: 310-2-3-2 球墨铸铁给水管（DN200) 数量计算表
A2: 序号 | B2: 段落 | C2: 核算数量（m) | D2: 图纸数量（m) | E2: 备注
A3: 1 | C3: 100 | D3: 100 | E3: 第二测PS3-5-2
A4: 2
A5: 3
A6: 4
A7: 5
A8: 6
A9: 7
A10: 8
A21: 合计： | C21: =SUM(C3:C20) -> 100 | D21: =SUM(D3:D20) -> 100
A22: 计算： 复核： 监理: 日期:

Sheet 310-3 中央分隔带渗沟 
A1: 310-3 中央分隔带渗沟 数量计算表
A2: 序号 | B2: 段落 | C2: 核算数量（M) | D2: 图纸数量（M) | E2: 备注
A3: 1 | B3: K4+581-K4+717 | C3: 272 | D3: 272 | E3: 第二册PS2-4
A4: 2 | B4: K6+037-K6+710 | C4: 1156 | D4: 1156 | E4: 第二册PS2-4
A5: 3 | B5: K6+170-6+800 | C5: 90 | D5: 90 | E5: 第二册PS2-4
A6: 4 | B6: K6+800-K6+840 | C6: 40 | D6: 40 | E6: 第二册PS2-4
A7: 5 | B7: K7+080-K7+427 | C7: 347 | D7: 347 | E7: 第二册PS2-4
A8: 6
A9: 7
A10: 8
A21: 合计： | C21: =SUM(C3:C20) -> 1905 | D21: =SUM(D3:D20) -> 1905
A22: 计算： 复核： 监理: 日期:

Sheet 310-4 集水井 
A1: 310-4 集水井 数量计算表
A2: 序号 | B2: 段落 | C2: 核算数量（个 ) | D2: 图纸数量（个) | E2: 备注
A3: 1 | B3: K6+350 | C3: 1 | D3: 1 | E3: 第二册PS2-5
A4: 2 | B4: K6+400 | C4: 1 | D4: 1 | E4: 第二册PS2-5
A5: 3 | B5: K6+450 | C5: 1 | D5: 1 | E5: 第二册PS2-5
A6: 4 | B6: K6+515 | C6: 1 | D6: 1 | E6: 第二册PS2-5
A7: 5 | B7: K6+685 | C7: 1 | D7: 1 | E7: 第二册PS2-5
A8: 6 | B8: K6+765 | C8: 1 | D8: 1 | E8: 第二册PS2-5
A9: 7 | B9: K7+170 | C9: 1 | D9: 1 | E9: 第二册PS2-5
A10: 8 | B10: K7+230 | C10: 1 | D10: 1 | E10: 第二册PS2-5
A11: 9 | B11: K7+280 | C11: 1 | D11: 1 | E11: 第二册PS2-5
A12: 10 | B12: K7+345 | C12: 1 | D12: 1 | E12: 第二册PS2-5
A21: 合计： | C21: =SUM(C3:C20) -> 10 | D21: =SUM(D3:D20) -> 10
A22: 计算： 复核： 监理: 日期:

Sheet 310-5-1 矩形钢筋砼（内空1.1×1.1m）检查井
A1: 310-5-1 矩形钢筋砼（内空1.1×1.1m）检查井数量计算表
A2: 序号 | B2: 段落 | C2: 核算数量（个) | D2: 图纸数量（个) | E2: 备注
A3: 1 | B3: C、D匝道 | C3: 15 | D3: 15 | E3: 第二册PS3-1 第二册PS3-3 第二册PS3-5-1
A4: 2
A5: 3
A6: 4
A7: 5
A8: 6
A9: 7
A10: 8
A21: 合计： | C21: =SUM(C3:C20) -> 15 | D21: =SUM(D3:D20) -> 15
A22: 计算： 复核： 监理: 日期:

Sheet 310-5-2 矩形钢筋砼（内空1.25×1.25）检查井
A1: 310-5-2 矩形钢筋砼（内空1.25×1.25）检查井数量计算表
A2: 序号 | B2: 段落 | C2: 核算数量（个) | D2: 图纸数量（个) | E2: 备注
A3: 1 | B3: D匝道 | C3: 4 | D3: 4 | E3: 第二册PS3-1 第二册PS3-3 第二册PS3-5-1
A4: 2
A5: 3
A6: 4
A7: 5
A8: 6
A9: 7
A10: 8
A21: 合计： | C21: =SUM(C3:C20) -> 4 | D21: =SUM(D3:D20) -> 4
A22: 计算： 复核： 监理: 日期:

Sheet 310-10-1 砖砌单篦雨水口
A1: 310-10-1 砖砌单篦雨水口数量计算表
A2: 序号 | B2: 段落 | C2: 核算数量（个) | D2: 图纸数量（个) | E2: 备注
A3: 1 | B3: C/D匝道 | C3: 32 | D3: 32 | E3: 第二册PS3-1 第二册PS3-5-1
A4: 2
A5: 3
A6: 4
A7: 5
A8: 6
A9: 7
A10: 8
A21: 合计： | C21: =SUM(C3:C20) -> 32 | D21: =SUM(D3:D20) -> 32
A22: 计算： 复核： 监理: 日期:

Sheet 310-13-1 砂砾（碎石）透水层 路肩排水 
A1: 310-13-1 砂砾（碎石）透水层路肩排水数量计算表
A2: 序号 | B2: 段落 | C2: 长度 | E2: 核算数量（m2) | F2: 图纸数量（m2) | G2: 备注
C3: 左侧（m） | D3: 右侧（m）
A4: 1 | B4: K4+300-K4+316 | D4: 16 | E4: 1.4 | F4: 1.4 | G4: 第二册PS2-4 | H4: 挖
A5: 2 | B5: K4+316-K4+331 | D5: 15 | E5: 1.8 | F5: 1.8 | H5: 填
A6: 3 | B6: K4+581-K4+760 | D6: 179 | E6: 21.2 | F6: 21.2 | H6: 填
A7: 4 | B7: K4+760-K4+780 | D7: 20 | E7: 17.3 | F7: 17.3 | H7: 挖
A8: 5 | B8: K5+980-K6+180 | D8: 200 | E8: 29.2 | F8: 29.2 | H8: 挖
A9: 6 | B9: K6+180-K6+517 | D9: 337 | E9: 40 | F9: 40 | H9: 填
A10: 7 | B10: K6+517-K6+680 | D10: 163 | E10: 10.4 | F10: 10.4 | H10: 挖
A11: 8 | B11: K6+680-K6+800 | D11: 120 | E11: 14.2 | F11: 14.2 | H11: 填
A12: 9 | B12: K4+300-K4+331 | C12: 31 | E12: 3.7 | F12: 3.7 | H12: 填
A13: 10 | B13: K4+581-K4+780 | C13: 199 | E13: 4.9 | F13: 4.9 | H13: 挖
A14: 11 | B14: K5+980-K6+037 | C14: 57 | E14: 2.7 | F14: 2.7 | H14: 挖
A15: 12 | B15: ZK4+300-ZK4+331 | D15: 31 | E15: 5.4 | F15: 5.4 | H15: 挖
A16: 13 | B16: ZK4+722-ZK4+785 | D16: 63 | E16: 2.8 | F16: 2.8 | H16: 挖
A17: 14 | B17: ZK6+016-ZK6+048 | D17: 32 | E17: 2.7 | F17: 2.7 | H17: 挖
A18: 15 | B18: ZK4+300-ZK4+331 | C18: 31 | E18: 3.7 | F18: 3.7 | H18: 填
A19: 16 | B19: ZK4+586-ZK4+700 | C19: 114 | E19: 13.5 | F19: 13.5 | H19: 填
A20: 17 | B20: ZK4+700-ZK4+785 | C20: 85 | E20: 22.8 | F20: 22.8 | H20: 挖
A21: 18 | B21: ZK6+016-ZK6+280 | C21: 264 | E21: 19.9 | F21: 19.9 | H21: 挖
A22: 19 | B22: ZK6+280-ZK6+510 | C22: 230 | E22: 27.3 | F22: 27.3 | H22: 填
A23: 20 | B23: ZK6+510-ZK6+756 | C23: 246 | E23: 4.6 | F23: 4.6 | H23: 挖
A24: 21 | B24: ZK6+756-ZK6+809 | C24: 53 | E24: 6.3 | F24: 6.3 | H24: 填
A25: 22 | B25: K6+800-K6+840 | C25: 40 | D25: 40 | E25: 9.5 | F25: 9.5 | H25: 填
A26: 23 | B26: K7+080-K7+179 | D26: 99 | E26: 11.8 | F26: 11.8 | H26: 填
A27: 24 | B27: K7+080-K7+170 | C27: 90 | E27: 10.7 | F27: 10.7 | H27: 填
A28: 25 | B28: K7+179-K7+427 | D28: 248 | E28: 29.4 | F28: 29.4 | H28: 填
A29: 26 | B29: K7+171-K7+427 | C29: 256 | E29: 30.3 | F29: 30.3 | H29: 填
A30: 27 | B30: AK0+121-AK0+200 | C30: 79 | D30: 79 | E30: 18.7 | F30: 18.7 | H30: 填
A31: 28 | B31: AK0+200-AK0+366 | C31: 166 | D31: 166 | E31: 28.7 | F31: 28.7 | H31: 挖
A32: 29 | B32: AK0+386-AK0+461 | C32: 75 | D32: 75 | E32: 17.8 | F32: 17.8 | H32: 填
A33: 30 | B33: BK0+000-BK0+077 | C33: 77 | D33: 77 | E33: 18.4 | F33: 18.4 | H33: 填
A34: 31 | B34: BK0+097-BK0+117 | C34: 20 | D34: 20 | E34: 4.7 | F34: 4.7 | H34: 填
A35: 32 | B35: BK0+117-BK0+320 | C35: 203 | D35: 203 | E35: 35.1 | F35: 35.1 | H35: 挖
A36: 33 | B36: BK0+117-BK0+375 | C36: 258 | D36: 258 | E36: 61.2 | F36: 61.2 | H36: 填
A37: 34 | B37: CK0+000-CK0+255 | C37: 255 | D37: 255 | E37: 60.4 | F37: 60.4 | H37: 填
A38: 35 | B38: DK0+000-DK0+246 | C38: 245 | D38: 245 | E38: 58.3 | F38: 58.3 | H38: 填
A39: 合计： | E39: =SUM(E4:E38) -> 650.8 | F39: =SUM(F4:F38) -> 650.8
A40: 计算： 复核： 监理: 日期:

Sheet 310-13-2 透水土工布 路肩排水 
A1: 310-13-2 透水土工布 路肩排水 数量计算表
A2: 序号 | B2: 段落 | C2: 长度 | E2: 核算数量（m2) | F2: 图纸数量（m2) | G2: 备注
C3: 左侧（m） | D3: 右侧（m）
A4: 1 | B4: K4+300-K4+316 | D4: 16 | E4: 13.6 | F4: 13.6 | G4: 第二册PS2-4 | H4: 挖
A5: 2 | B5: K4+316-K4+331 | D5: 15 | E5: 14.7 | F5: 14.7 | H5: 填
A6: 3 | B6: K4+581-K4+760 | D6: 179 | E6: 175.4 | F6: 175.4 | H6: 填
A7: 4 | B7: K4+760-K4+780 | D7: 20 | E7: 17 | F7: 17 | H7: 挖
A8: 5 | B8: K5+980-K6+180 | D8: 200 | E8: 170 | F8: 170 | H8: 挖
A9: 6 | B9: K6+180-K6+517 | D9: 337 | E9: 330.3 | F9: 330.3 | H9: 填
A10: 7 | B10: K6+517-K6+680 | D10: 163 | E10: 138.6 | F10: 138.6 | H10: 挖
A11: 8 | B11: K6+680-K6+800 | D11: 120 | E11: 117.6 | F11: 117.6 | H11: 填
A12: 9 | B12: K4+300-K4+331 | C12: 31 | E12: 30.4 | F12: 30.4 | H12: 填
A13: 10 | B13: K4+581-K4+780 | C13: 199 | E13: 169.2 | F13: 169.2 | H13: 挖
A14: 11 | B14: K5+980-K6+037 | C14: 57 | E14: 48.5 | F14: 48.5 | H14: 挖
A15: 12 | B15: ZK4+300-ZK4+331 | D15: 31 | E15: 26.4 | F15: 26.4 | H15: 挖
A16: 13 | B16: ZK4+722-ZK4+785 | D16: 63 | E16: 53.6 | F16: 53.6 | H16: 挖
A17: 14 | B17: ZK6+016-ZK6+048 | D17: 32 | E17: 27.2 | F17: 27.2 | H17: 挖
A18: 15 | B18: ZK4+300-ZK4+331 | C18: 31 | E18: 30.4 | F18: 30.4 | H18: 填
A19: 16 | B19: ZK4+586-ZK4+700 | C19: 114 | E19: 111.7 | F19: 111.7 | H19: 填
A20: 17 | B20: ZK4+700-ZK4+785 | C20: 85 | E20: 72.3 | F20: 72.3 | H20: 挖
A21: 18 | B21: ZK6+016-ZK6+280 | C21: 264 | E21: 224.4 | F21: 224.4 | H21: 挖
A22: 19 | B22: ZK6+280-ZK6+510 | C22: 230 | E22: 225.4 | F22: 225.4 | H22: 填
A23: 20 | B23: ZK6+510-ZK6+756 | C23: 246 | E23: 209.1 | F23: 209.1 | H23: 挖
A24: 21 | B24: ZK6+756-ZK6+809 | C24: 53 | E24: 51.9 | F24: 51.9 | H24: 填
A25: 22 | B25: K6+800-K6+840 | C25: 40 | D25: 40 | E25: 78.4 | F25: 78.4 | H25: 填
A26: 23 | B26: K7+080-K7+179 | D26: 99 | E26: 97.5 | F26: 97.5 | H26: 填
A27: 24 | B27: K7+080-K7+170 | C27: 90 | E27: 88.5 | F27: 88.5 | H27: 填
A28: 25 | B28: K7+179-K7+427 | D28: 248 | E28: 242.6 | F28: 242.6 | H28: 填
A29: 26 | B29: K7+171-K7+427 | C29: 256 | E29: 250.5 | F29: 250.5 | H29: 填
A30: 27 | B30: AK0+121-AK0+200 | C30: 79 | D30: 79 | E30: 154.7 | F30: 154.7 | H30: 填
A31: 28 | B31: AK0+200-AK0+366 | C31: 166 | D31: 166 | E31: 282.2 | F31: 282.2 | H31: 挖
A32: 29 | B32: AK0+386-AK0+461 | C32: 75 | D32: 75 | E32: 147.2 | F32: 147.2 | H32: 填
A33: 30 | B33: BK0+000-BK0+077 | C33: 77 | D33: 77 | E33: 151.7 | F33: 151.7 | H33: 填
A34: 31 | B34: BK0+097-BK0+117 | C34: 20 | D34: 20 | E34: 38.4 | F34: 38.4 | H34: 填
A35: 32 | B35: BK0+117-BK0+320 | C35: 203 | D35: 203 | E35: 345.1 | F35: 345.1 | H35: 挖
A36: 33 | B36: BK0+117-BK0+375 | C36: 258 | D36: 258 | E36: 505.2 | F36: 505.2 | H36: 填
A37: 34 | B37: CK0+000-CK0+255 | C37: 255 | D37: 255 | E37: 499.1 | F37: 499.1 | H37: 填
A38: 35 | B38: DK0+000-DK0+246 | C38: 245 | D38: 245 | E38: 481.2 | F38: 481.2 | H38: 填
A39: 合计： | E39: =SUM(E4:E38) -> 5620 | F39: =SUM(F4:F38) -> 5620
A40: 计算： 复核： 监理: 日期:

Sheet 310-13-5 防渗土工布 路肩排水
A1: 310-13-5 防渗土工布 路肩排水 数量计算表
A2: 序号 | B2: 段落 | C2: 长度 | E2: 核算数量（m2) | F2: 图纸数量（m2) | G2: 备注
C3: 左侧（m） | D3: 右侧（m）
A4: 1 | B4: K4+300-K4+316 | D4: 16 | E4: 9.6 | F4: 9.6 | G4: 第二册PS2-4 | H4: 挖
A5: 2 | B5: K4+316-K4+331 | D5: 15 | E5: 17 | F5: 17 | H5: 填
A6: 3 | B6: K4+581-K4+760 | D6: 179 | E6: 202.3 | F6: 202.3 | H6: 填
A7: 4 | B7: K4+760-K4+780 | D7: 20 | E7: 12 | F7: 12 | H7: 挖
A8: 5 | B8: K5+980-K6+180 | D8: 200 | E8: 120 | F8: 120 | H8: 挖
A9: 6 | B9: K6+180-K6+517 | D9: 337 | E9: 380.8 | F9: 380.8 | H9: 填
A10: 7 | B10: K6+517-K6+680 | D10: 163 | E10: 97.8 | F10: 97.8 | H10: 挖
A11: 8 | B11: K6+680-K6+800 | D11: 120 | E11: 135.6 | F11: 135.6 | H11: 填
A12: 9 | B12: K4+300-K4+331 | C12: 31 | E12: 35 | F12: 35 | H12: 填
A13: 10 | B13: K4+581-K4+780 | C13: 199 | E13: 119.4 | F13: 119.4 | H13: 挖
A14: 11 | B14: K5+980-K6+037 | C14: 57 | E14: 34.2 | F14: 34.2 | H14: 挖
A15: 12 | B15: ZK4+300-ZK4+331 | D15: 31 | E15: 18.6 | F15: 18.6 | H15: 挖
A16: 13 | B16: ZK4+722-ZK4+785 | D16: 63 | E16: 37.8 | F16: 37.8 | H16: 挖
A17: 14 | B17: ZK6+016-ZK6+048 | D17: 32 | E17: 19.2 | F17: 19.2 | H17: 挖
A18: 15 | B18: ZK4+300-ZK4+331 | C18: 31 | E18: 35 | F18: 35 | H18: 填
A19: 16 | B19: ZK4+586-ZK4+700 | C19: 114 | E19: 128.8 | F19: 128.8 | H19: 填
A20: 17 | B20: ZK4+700-ZK4+785 | C20: 85 | E20: 51 | F20: 51 | H20: 挖
A21: 18 | B21: ZK6+016-ZK6+280 | C21: 264 | E21: 158.4 | F21: 158.4 | H21: 挖
A22: 19 | B22: ZK6+280-ZK6+510 | C22: 230 | E22: 259.9 | F22: 259.9 | H22: 填
A23: 20 | B23: ZK6+510-ZK6+756 | C23: 246 | E23: 147.6 | F23: 147.6 | H23: 挖
A24: 21 | B24: ZK6+756-ZK6+809 | C24: 53 | E24: 59.9 | F24: 59.9 | H24: 填
A25: 22 | B25: K6+800-K6+840 | C25: 40 | D25: 40 | E25: 90.4 | F25: 90.4 | H25: 填
A26: 23 | B26: K7+080-K7+179 | D26: 99 | E26: 112.4 | F26: 112.4 | H26: 填
A27: 24 | B27: K7+080-K7+170 | C27: 90 | E27: 102.1 | F27: 102.1 | H27: 填
A28: 25 | B28: K7+179-K7+427 | D28: 248 | E28: 279.8 | F28: 279.8 | H28: 填
A29: 26 | B29: K7+171-K7+427 | C29: 256 | E29: 288.8 | F29: 288.8 | H29: 填
A30: 27 | B30: AK0+121-AK0+200 | C30: 79 | D30: 79 | E30: 178.4 | F30: 178.4 | H30: 填
A31: 28 | B31: AK0+200-AK0+366 | C31: 166 | D31: 166 | E31: 199.2 | F31: 199.2 | H31: 挖
A32: 29 | B32: AK0+386-AK0+461 | C32: 75 | D32: 75 | E32: 169.8 | F32: 169.8 | H32: 填
A33: 30 | B33: BK0+000-BK0+077 | C33: 77 | D33: 77 | E33: 174.9 | F33: 174.9 | H33: 填
A34: 31 | B34: BK0+097-BK0+117 | C34: 20 | D34: 20 | E34: 44.3 | F34: 44.3 | H34: 填
A35: 32 | B35: BK0+117-BK0+320 | C35: 203 | D35: 203 | E35: 243.6 | F35: 243.6 | H35: 挖
A36: 33 | B36: BK0+117-BK0+375 | C36: 258 | D36: 258 | E36: 582.6 | F36: 582.6 | H36: 填
A37: 34 | B37: CK0+000-CK0+255 | C37: 255 | D37: 255 | E37: 575.4 | F37: 575.4 | H37: 填
A38: 35 | B38: DK0+000-DK0+246 | C38: 245 | D38: 245 | E38: 554.8 | F38: 554.8 | H38: 填
A39: 合计： | E39: =SUM(E4:E38) -> 5676.4 | F39: =SUM(F4:F38) -> 5676.4
A40: 计算： 复核： 监理: 日期:

Sheet 310-15 流水槽
A1: 310-15 流水槽 数量计算表
A2: 序号 | B2: 段落 | C2: 核算数量（m) | D2: 图纸数量（m) | E2: 备注
A3: 1 | B3: K6+292-K6+800 | C3: 508 | D3: 508 | E3: 第二册PS2-5
A4: 2 | B4: K7+110-K7+390 | C4: 280 | D4: 280 | E4: 第二册PS2-5
A5: 3
A6: 4
A7: 5
A8: 6
A9: 7
A10: 8
A21: 合计： | C21: =SUM(C3:C20) -> 788 | D21: =SUM(D3:D20) -> 788
A22: 计算： 复核： 监理: 日期:

Sheet 310-16 急流槽
A1: 310-16 急流槽 数量计算表
A2: 序号 | B2: 段落 | C2: 核算数量（m) | D2: 图纸数量（m) | E2: 备注
A3: 1 | B3: K6+400 | C3: 13.3 | D3: 13.3 | E3: 第二册PS2-5
A4: 2 | B4: K6+450 | C4: 11.4 | D4: 11.4 | E4: 第二册PS2-5
A5: 3
A6: 4
A7: 5
A8: 6
A9: 7
A10: 8
A21: 合计： | C21: =SUM(C3:C20) -> 24.7 | D21: =SUM(D3:D20) -> 24.7
A22: 计算： 复核： 监理: 日期:

Sheet Sheet2
